[2020-08-21 08:58:07,417 - django.request - ERROR] - Internal Server Error: /
Traceback (most recent call last):
  File "/home/lightwarrior/venvbox/bookstore-app/lib/python3.6/site-packages/django/db/backends/utils.py", line 86, in _execute
    return self.cursor.execute(sql, params)
  File "/home/lightwarrior/venvbox/bookstore-app/lib/python3.6/site-packages/django/db/backends/sqlite3/base.py", line 396, in execute
    return Database.Cursor.execute(self, query, params)
sqlite3.OperationalError: no such table: books_savehttprequests

The above exception was the direct cause of the following exception:

Traceback (most recent call last):
  File "/home/lightwarrior/venvbox/bookstore-app/lib/python3.6/site-packages/django/core/handlers/exception.py", line 34, in inner
    response = get_response(request)
  File "/home/lightwarrior/Dropbox/sp-bootstrap/testground/Django-book-store/books/middleware/save_requests.py", line 13, in middleware
    request_instance.save()
  File "/home/lightwarrior/venvbox/bookstore-app/lib/python3.6/site-packages/django/db/models/base.py", line 746, in save
    force_update=force_update, update_fields=update_fields)
  File "/home/lightwarrior/venvbox/bookstore-app/lib/python3.6/site-packages/django/db/models/base.py", line 784, in save_base
    force_update, using, update_fields,
  File "/home/lightwarrior/venvbox/bookstore-app/lib/python3.6/site-packages/django/db/models/base.py", line 886, in _save_table
    results = self._do_insert(cls._base_manager, using, fields, returning_fields, raw)
  File "/home/lightwarrior/venvbox/bookstore-app/lib/python3.6/site-packages/django/db/models/base.py", line 925, in _do_insert
    using=using, raw=raw,
  File "/home/lightwarrior/venvbox/bookstore-app/lib/python3.6/site-packages/django/db/models/manager.py", line 82, in manager_method
    return getattr(self.get_queryset(), name)(*args, **kwargs)
  File "/home/lightwarrior/venvbox/bookstore-app/lib/python3.6/site-packages/django/db/models/query.py", line 1204, in _insert
    return query.get_compiler(using=using).execute_sql(returning_fields)
  File "/home/lightwarrior/venvbox/bookstore-app/lib/python3.6/site-packages/django/db/models/sql/compiler.py", line 1377, in execute_sql
    cursor.execute(sql, params)
  File "/home/lightwarrior/venvbox/bookstore-app/lib/python3.6/site-packages/django/db/backends/utils.py", line 100, in execute
    return super().execute(sql, params)
  File "/home/lightwarrior/venvbox/bookstore-app/lib/python3.6/site-packages/django/db/backends/utils.py", line 68, in execute
    return self._execute_with_wrappers(sql, params, many=False, executor=self._execute)
  File "/home/lightwarrior/venvbox/bookstore-app/lib/python3.6/site-packages/django/db/backends/utils.py", line 77, in _execute_with_wrappers
    return executor(sql, params, many, context)
  File "/home/lightwarrior/venvbox/bookstore-app/lib/python3.6/site-packages/django/db/backends/utils.py", line 86, in _execute
    return self.cursor.execute(sql, params)
  File "/home/lightwarrior/venvbox/bookstore-app/lib/python3.6/site-packages/django/db/utils.py", line 90, in __exit__
    raise dj_exc_value.with_traceback(traceback) from exc_value
  File "/home/lightwarrior/venvbox/bookstore-app/lib/python3.6/site-packages/django/db/backends/utils.py", line 86, in _execute
    return self.cursor.execute(sql, params)
  File "/home/lightwarrior/venvbox/bookstore-app/lib/python3.6/site-packages/django/db/backends/sqlite3/base.py", line 396, in execute
    return Database.Cursor.execute(self, query, params)
django.db.utils.OperationalError: no such table: books_savehttprequests
[2020-08-21 08:59:33,398 - books_app - INFO] - Created new book with title: my book
[2020-08-21 09:00:49,927 - django.request - WARNING] - Not Found: /favicon.ico
